Workbook

Sheet PLAYERS
A1: Rank | B1: NAME | C1: Player | D1: Team | E1: Seed | F1: Region | G1: PPG | I1: Venmo - @alex-friedman-14
A2: 1 | B2: Mike | C2: Cameron Boozer F | D2: Duke | E2: 1 | F2: E | G2: 22.7
A3: 2 | B3: Brian | C3: Thomas Haugh F | D3: Florida | E3: 1 | F3: S | G3: 17.2
A4: 3 | B4: Kyle | C4: Brayden Burries G | D4: Arizona | E4: 1 | F4: W | G4: 16
A5: 4 | B5: Dan | C5: Alex Condon F | D5: Florida | E5: 1 | F5: S | G5: 14.8
A6: 5 | B6: Puff | C6: Yaxel Lendeborg F | D6: Michigan | E6: 1 | F6: M | G6: 14.7
A7: 6 | B7: Nick | C7: Isaiah Evans G | D7: Duke | E7: 1 | F7: E | G7: 14.5
A8: 7 | B8: Alex | C8: Koa Peat F | D8: Arizona | E8: 1 | F8: W | G8: 13.8
A9: 8 | B9: Nick | C9: Morez Johnson Jr. F | D9: Michigan | E9: 1 | F9: M | G9: 13.7
A10: 9 | B10: Tim | C10: Milan Momcilovic F | D10: Iowa State | E10: 2 | F10: M | G10: 17
A11: 10 | B11: Dan | C11: Jaden Bradley G | D11: Arizona | E11: 1 | F11: W | G11: 13.4
A12: 11 | B12: RJ | C12: Joshua Jefferson F | D12: Iowa State | E12: 2 | F12: M | G12: 16.6
A13: 12 | B13: Zeth | C13: Darius Acuff Jr. G | D13: Arkansas | E13: 4 | F13: W | G13: 22.2
... A47: 46 | B47: Tim | C47: Robert Wright III G | D47: BYU | E47: 6 | F47: W | G47: 18.5
A48: 47 | C48: Mikel Brown Jr. G** (Out weekend) | D48: Louisville | E48: 6 | F48: E | G48: 18.2
A49: 48 | B49: Mike | C49: John Blackwell G | D49: Wisconsin | E49: 5 | F49: W | G49: 18.3
A50: 49 | B50: Zeth | C50: Ja'Kobi Gillespie G | D50: Tennessee | E50: 6 | F50: M | G50: 18
A51: 50 | B51: Brian | C51: Meleek Thomas G | D51: Arkansas | E51: 4 | F51: W | G51: 15.4
A52: 51 | B52: Puff | C52: Milos Uzan G | D52: Houston | E52: 2 | F52: S | G52: 11.5
A53: 52 | B53: Kyle | C53: Andrej Stojakovic G | D53: Illinois | E53: 3 | F53: S | G53: 13.3
A54: 53 | B54: Kyle | C54: Kylan Boswell G | D54: Illinois | E54: 3 | F54: S | G54: 13.3
A55: 54 | B55: Alex | C55: Nate Ament F** (Ankle) | D55: Tennessee | E55: 6 | F55: M | G55: 17.4
A56: 55 | B56: Tim | C56: Silas Demary Jr. G | D56: Uconn | E56: 2 | F56: E | G56: 11.1
A57: 56 | B57: RJ | C57: David Mirkovic F | D57: Illinois | E57: 3 | F57: S | G57: 13.2
A58: 57 | B58: Kyle | C58: Anthony Dell'Orso G | D58: Arizona | E58: 1 | F58: W | G58: 8.7
A59: 58 | B59: Puff | C59: Jaxon Kohler F | D59: Michigan State | E59: 3 | F59: E | G59: 12.8
A60: 59 | B60: RJ | C60: Tre White G | D60: Kansas | E60: 4 | F60: E | G60: 14.3
... A71: 70 | B71: Mike | C71: Melvin Council Jr. G | D71: Kansas | E71: 4 | F71: E | G71: 13.4
A72: 71 | C72: Patrick Ngongba II C** (Foot) | D72: Duke | E72: 1 | F72: E | G72: 10.7
A73: 72 | B73: RJ | C73: Latrell Wrightsell G | D73: Alabama | E73: 4 | F73: M | G73: 13.3
A74: 73 | B74: David | C74: Otega Oweh G | D74: Kentucky | E74: 7 | F74: M | G74: 18.2
A75: 74 | B75: Dan | C75: Oscar Cluff C | D75: Purdue | E75: 2 | F75: W | G75: 9.8
A76: 75 | B76: Nick | C76: Trevon Brazile F | D76: Arkansas | E76: 4 | F76: W | G76: 13.1
A77: 76 | B77: Alex | C77: Tyler Bilodeau F** (Knee) | D77: UCLA | E77: 7 | F77: E | G77: 18
A78: 77 | B78: Brian | C78: Coen Carr F | D78: Michigan State | E78: 3 | F78: E | G78: 11.5
A79: 78 | B79: Zeth | C79: Bennett Stirtz G | D79: Iowa | E79: 9 | F79: S | G79: 20.2
A80: 79 | B80: Nick | C80: Chris Cenac Jr. F | D80: Houston | E80: 2 | F80: S | G80: 9.4
A81: 80 | B81: Nick | C81: Tyon Grant-Foster G | D81: Gonzaga | E81: 3 | F81: W | G81: 11.2
A82: 81 | C82: Roddy Gayle Jr. G** (Ankle) | D82: Michigan | E82: 1 | F82: M | G82: 7.4
A83: 82 | B83: Puff | C83: Tavari Johnson G | D83: Akron | E83: 12 | F83: M | G83: 20.1
...

Sheet PICKS
A1: Draft Order | B1: 1 | D1: 2 | F1: 3 | H1: 4 | J1: 5 | L1: 6 | N1: 7 | P1: 8 | R1: 9 | T1: 10 | V1: 11
A2: Real Name | B2: Mike | D2: Kyle Sherer | F2: Brian Baker | H2: Puff | J2: Tim | K2: Team | L2: Alex | M2: Team | N2: Zeth Hearld | O2: Team | P2: Nick | Q2: Team | R2: Dan | S2: Team | T2: RJ Armstrong | U2: Team | V2: Dave | W2: Team
A3: Team Name | B3: Joe Mama | D3: THE Hanover U | J3: JustBeatDan | R3: HanoverEZ | T3: Hoops, There it is
A4: 1 | B4: Boozer | C4: Duke | D4: Brayden Burries G | E4: Arizona | F4: Thomas Haugh | G4: Florida | H4: Yaxel Lendeborg F | I4: =iferror(vlookup(H4,PLAYERS!$C:$D,2,false),"") -> Michigan | J4: Graham Ike | K4: Gonzaga | L4: Koa Peat | M4: Arizona | N4: Darius Acuff | O4: Arkansas | P4: Isaiah Evans | Q4: Duke | R4: Jaden Bradley | S4: =iferror(vlookup(R4,PLAYERS!$C:$D,2,true),"") -> Idaho | T4: Joshua Jefferson F | U4: Iowa State | V4: Kingston Fleming | W4: Houston
A5: 2 | B5: Darryn Peterson | C5: Kansas | D5: Jeremy Fears | E5: Michigan | F5: Fletcher Loyer | G5: Purdue | H5: Solo Ball G | I5: =iferror(vlookup(H5,PLAYERS!$C:$D,2,false),"") -> Uconn | J5: milan momcilovic | K5: Iowa state | L5: Braden Smith | M5: Purdue | N5: Emanuel Sharp | O5: Houston | P5: Morez Johnson Jr. | Q5: Michigan | R5: Alex Condon | S5: Florida | T5: Keaton Wagler G | U5: Illinois | V5: Labaron Philon | W5: Alabama
A6: 3 | B6: Boogie Fland | C6: Florida | D6: Tamin Lipsey G | E6: Iowa | F6: Trey Kaufman-Renn | G6: Purdue | H6: Xaivian Lee G | I6: =iferror(vlookup(H6,PLAYERS!$C:$D,2,false),"") -> Florida | J6: AJ Dybansta | K6: BYU | L6: Aday Mara | M6: Michigan | N6: Nick Boyd WIS | O6: Wis | P6: Rueben Chinyelu C | Q6: Florida | R6: Motiejus Krivas C | S6: Arizona | T6: Tarris Reed Jr. C | U6: Uconn | V6: Pryce Sandfort | W6: Nebraska
A7: 4 | B7: Christian Anderson G** (Groin) | C7: Texas Tech | D7: Kylan Boswell G | E7: Illinois | F7: Tobe Awaka | G7: Arizona | H7: Jaxon Kohler F | I7: =iferror(vlookup(H7,PLAYERS!$C:$D,2,false),"") -> Michigan State | J7: Ryan Conwell | K7: Louisville | L7: Braylon Mullins | M7: UConn | N7: Ja'Kobi Gillespi | O7: Tenn | P7: Ivan Kharchenkov F | Q7: Arizona | R7: Alex Karaban F | S7: UConn | T7: Thijs De Ridder F | U7: Virginia | V7: Tyler Tanner | W7: Vanderbilt
A8: 5 | B8: John Blackwell G | C8: Wisconsin | D8: Andrej Stojakovic G | E8: Illinois | F8: Meleek Thomas | G8: Arkansas | H8: Milos Uzan G | I8: =iferror(vlookup(H8,PLAYERS!$C:$D,2,false),"") -> Houston | J8: Silas Demary Jr | K8: Uconn | L8: Eliott Cadeau | M8: Michigan | N8: Bennett Stirtz | O8: Iowa | P8: Urban Klavzar | Q8: Florida | R8: Oscar Cluff C | S8: Purdue | T8: David Mirkovic F | U8: Illinois | V8: Bruce Thornton | W8: OSU
A9: 6 | B9: Melvin Council Jr. | C9: Kansas | D9: Donovan Atwell G | E9: Texas Tech | F9: Coen Carr | G9: MSU | H9: Malik Thomas G | I9: =iferror(vlookup(H9,PLAYERS!$C:$D,2,false),"") -> Virginia | J9: Zuby Ejiofor | K9: St John | L9: Nate Ament | M9: Tennessee | N9: Tre Donaldson | O9: Miami | P9: Trey McKenney G | Q9: Michigan | R9: Flory Bidunga | S9: Kansas | T9: Tre White G | U9: Kansas | V9: Otega Oweh | W9: Kentucky
A10: 7 | B10: Herni Veesaar | C10: North Carolina | D10: Anthony Dell'Orso G | E10: Arizona | F10: Duke Miles | G10: Vanderbilt | H10: Jeremiah Wilkinson G | I10: =iferror(vlookup(H10,PLAYERS!$C:$D,2,false),"") -> Georgia | J10: Robert Writght III | K10: BYU | L10: Malik Reanu | M10: Miami | N10: Seth Trimble | O10: UNC | P10: Trevon Brazile F | Q10: Arkansas | R10: Cayden Boozer | S10: Duke | T10: Latrell Wrightsell G | U10: Alabama | V10: Dailyn Swain | W10: Texas First 4
A11: 8 | B11: Bryce Hopkins | C11: St. Johns | D11: Amari Allen F | E11: Alabama | F11: Nolan Winter | G11: Wisconsin | H11: John Mobley Jr. G | I11: =iferror(vlookup(H11,PLAYERS!$C:$D,2,false),"") -> Ohio State | J11: Mikey Lewis | K11: St Marys | L11: Donovan Dent | M11: UCLA | N11: Nimari Burnett | O11: Michigan | P11: Chris Cenac Jr. F | Q11: Houston | R11: Dame Sarr | S11: Duke | T11: Rienk Mast F | U11: Nebraska | V11: Carson Cooper | W11: MSU
A12: 9 | B12: Larry Johnson | C12: McNeese | D12: C.J. Cox G | E12: Purdue | F12: Blake Buchanan | G12: Iowa State | H12: Devin Royal F | I12: =iferror(vlookup(H12,PLAYERS!$C:$D,2,false),"") -> Ohio State | J12: Sam Lewis | K12: Virginia | L12: Peter Sudar/Boopie Miller | M12: Miami Oh, SMU | N12: Tomislav Ivisic C | O12: Illinois | P12: Tyon Grant-Foster G | Q12: Gonzaga | R12: MJ Collins Jr | S12: Utah | T12: Jacari White G | U12: Virginia | V12: Rashaun Agee | W12: Texas A&M
A13: 10 | B13: Billy Richmond III | C13: Arkansas | D13: Tyler Nickel F | E13: Vanderbilt | F13: Joseph Tugler | G13: Houston | H13: Tavari Johnson G | I13: =iferror(vlookup(H13,PLAYERS!$C:$D,2,false),"") -> Akron | J13: Trent Perry | K13: UCLA | L13: Tyler Biladou | M13: UCLA | N13: Mark Mitchell G | O13: Missouri | P13: Killyan Toure G | Q13: Iowa State | R13: Braden Frager | S13: Nebraska | T13: Jamarques Lawrence G | U13: Nebraska | V13: Matas Vokietaitis C | W13: Texas
A14: 11 | B14: Joshua Dent | C14: Saint Marys | D14: Devin Royal FBraden Frager F | E14: Nebraska | F14: Kur Teng | G14: MSU | H14: Mason Falslev G | I14: =iferror(vlookup(H14,PLAYERS!$C:$D,2,false),"") -> Utah State | J14: Dominique Daniels Jr. G | K14: CA Baptist | L14: Jaron Pierre/Bryan Bars | M14: SMU/Miami Oh | N14: Izaiyah Nelson F | O14: South Florida | P14: Malique Ewin F | Q14: Arkansas | R14: J'Vonne Hadley G | S14: Louisville | T14: Mario Saint-Supery G | U14: Gonzaga | V14: Wes Enis G | W14: South Florida
A15: 12 | B15: Oziyah Sellers | C15: St. Johns | D15: Nikolas Khamenia G | E15: Duke | F15: Davis Fogle | G15: Gonzaga | H15: Chance Mallory G | I15: =iferror(vlookup(H15,PLAYERS!$C:$D,2,false),"") -> Virginia | J15: Cruz Davis | K15: Hofstra | L15: JP Estralla | M15: Tennessee | N15: Terrence Hill Jr. G | O15: VCU | P15: Riley Kugel G | Q15: UCF | R15: Isaiah Brown | S15: Florida | T15: Jamarion Batemon G | U15: Iowa State | V15: Jayden Stone G | W15: Missouri
I16: =iferror(vlookup(H16,PLAYERS!$C:$D,2,false),"")
I17: =iferror(vlookup(H17,PLAYERS!$C:$D,2,false),"")
I18: =iferror(vlookup(H18,PLAYERS!$C:$D,2,false),"")
I19: =iferror(vlookup(H19,PLAYERS!$C:$D,2,false),"")
I20: =iferror(vlookup(H20,PLAYERS!$C:$D,2,false),"")
I21: =iferror(vlookup(H21,PLAYERS!$C:$D,2,false),"")
A22: $ | B22: 1100 | I22: =iferror(vlookup(H22,PLAYERS!$C:$D,2,false),"")
I23: =iferror(vlookup(H23,PLAYERS!$C:$D,2,false),"")
A24: 3rd | B24: -100 | I24: =iferror(vlookup(H24,PLAYERS!$C:$D,2,false),"")
A25: 2nd | B25: -200 | I25: =iferror(vlookup(H25,PLAYERS!$C:$D,2,false),"")
A26: 1st | B26: -560
A27: Round winner | B27: $40/round only can win once

Sheet ScoreBoard
B2: Round 1 | C2: Round 2 | D2: Round 3 | E2: Round 4 | F2: Round 5 | G2: Round 6 | H2: Points Total
A3: Mike | H3: =sum(B3:G3) -> 0
A4: Kyle Sherer | H4: =sum(B4:G4) -> 0
A5: Brian Baker | H5: =sum(B5:G5) -> 0
A6: Puff | H6: =sum(B6:G6) -> 0
A7: Tim | H7: =sum(B7:G7) -> 0
A8: Alex | H8: =sum(B8:G8) -> 0
A9: Zeth Hearld | H9: =sum(B9:G9) -> 0
A10: Nick | H10: =sum(B10:G10) -> 0
A11: Dan | H11: =sum(B11:G11) -> 0
A12: RJ Armstrong | H12: =sum(B12:G12) -> 0
A13: Dave | H13: =sum(B13:G13) -> 0

Sheet By Team
B1: MIDWEST | E1: SOUTH | H1: EAST | K1: WEST
B3: Player | C3: PPG | E3: Player | F3: PPG | H3: Player | I3: PPG | K3: Player | L3: PPG
A5: 1 | B5: Michigan | E5: Florida | H5: Duke | K5: Arizona
B6: Yaxel Lendeborg F | C6: 14.7 | E6: Thomas Haugh F | F6: 17.2 | H6: Cameron Boozer F | I6: 22.7 | K6: Brayden Burries G | L6: 16
B7: Morez Johnson Jr. F | C7: 13.7 | E7: Alex Condon F | F7: 14.8 | H7: Isaiah Evans G | I7: 14.5 | K7: Koa Peat F | L7: 13.8
B8: Aday Mara C | C8: 11.3 | E8: Xaivian Lee G | F8: 11.6 | H8: Patrick Ngongba II C** (Foot) | I8: 10.7 | K8: Jaden Bradley G | L8: 13.4
B9: Elliot Cadeau G | C9: 9.9 | E9: Boogie Fland G | F9: 11.6 | H9: Cayden Boozer G | I9: 6.5 | K9: Motiejus Krivas C | L9: 10.8
B10: Trey McKenney G | C10: 9.6 | E10: Rueben Chinyelu C | F10: 11.4 | H10: Dame Sarr G | I10: 6.2 | K10: Ivan Kharchenkov F | L10: 9.8
B11: Nimari Burnett G | C11: 8.4 | E11: Urban Klavzar G | F11: 9.9 | H11: Nikolas Khamenia G | I11: 5.4 | K11: Tobe Awaka F | L11: 9.6
B12: Roddy Gayle Jr. G** (Ankle) | C12: 7.4 | E12: Isaiah Brown G | F12: 5.7 | H12: Maliq Brown F | I12: 5 | K12: Anthony Dell'Orso G | L12: 8.7
B13: Will Tschetter F | C13: 4 | E13: Micah Handlogten C | F13: 4.2 | H13: Caleb Foster** (Foot Fracture) | I13: 8.5 | K13: Dwayne Aristode F | L13: 4.6
A15: 2 | B15: Iowa State | E15: Houston | H15: Uconn | K15: Purdue
B16: Milan Momcilovic F | C16: 17 | E16: Kingston Flemings G | F16: 16.5 | H16: Solo Ball G | I16: 13.9 | K16: Braden Smith G | L16: 14.9
B17: Joshua Jefferson F | C17: 16.6 | E17: Emanuel Sharp G | F17: 15.8 | H17: Tarris Reed Jr. C | I17: 13.8 | K17: Fletcher Loyer G | L17: 13.6
B18: Tamin Lipsey G | C18: 13.3 | E18: Milos Uzan G | F18: 11.5 | H18: Alex Karaban F | I18: 12.9 | K18: Trey Kaufman-Renn F | L18: 13.4
B19: Killyan Toure G | C19: 8.3 | E19: Chris Cenac Jr. F | F19: 9.4 | H19: Braylon Mullins G | I19: 12 | K19: Oscar Cluff C | L19: 9.8
B20: Blake Buchanan F | C20: 8.2 | E20: Joseph Tugler F | F20: 8 | H20: Silas Demary Jr. G | I20: 11.1 | K20: C.J. Cox G | L20: 8.5
B21: Jamarion Batemon G | C21: 7 | E21: Mercy Miller G | F21: 4.5 | H21: Eric Reibe C | I21: 6.7 | K21: Daniel Jacobsen C | L21: 6.4
A23: 3 | B23: Virginia | E23: Illinois | H23: Michigan State | K23: Gonzaga
B24: Thijs De Ridder F | C24: 15.9 | E24: Keaton Wagler G | F24: 17.9 | H24: Jeremy Fears Jr. G | I24: 15.5 | K24: Graham Ike F | L24: 19.7
B25: Malik Thomas G | C25: 12.1 | E25: Kylan Boswell G | F25: 13.3 | H25: Jaxon Kohler F | I25: 12.8 | K25: Tyon Grant-Foster G | L25: 11.2
B26: Sam Lewis G | C26: 10.4 | E26: Andrej Stojakovic G | F26: 13.3 | H26: Coen Carr F | I26: 11.5 | K26: Mario Saint-Supery G | L26: 8.6
B27: Chance Mallory G | C27: 9.6 | E27: David Mirkovic F | F27: 13.2 | H27: Carson Cooper C | I27: 10.7 | K27: Davis Fogle G | L27: 8.4
B28: Jacari White G | C28: 8.9 | E28: Tomislav Ivisic C | F28: 10 | H28: Kur Teng G | I28: 7.5 | K28: Adam Miller G | L28: 7.6
B29: Johann Grunloh C | C29: 7.7 | E29: Zvonimir Ivisic C | F29: 6.9 | H29: Jordan Scott F | I29: 5.9 | K29: Braden Huff F** (Knee) | L29: 17.8
A31: 4 | B31: Alabama | E31: Nebraska | H31: Kansas | K31: Arkansas
B32: Labaron Philon Jr. G | C32: 21.5 | E32: Pryce Sandfort F | F32: 17.9 | H32: Darryn Peterson G** (Ankle) | I32: 19.9 | K32: Darius Acuff Jr. G | L32: 22.2
B33: Aden Holloway G | C33: 16.8 | E33: Rienk Mast F | F33: 13.6 | H33: Tre White G | I33: 14.3 | K33: Meleek Thomas G | L33: 15.4
B34: Latrell Wrightsell G | C34: 13.3 | E34: Braden Frager F | F34: 11.7 | H34: Flory Bidunga F | I34: 13.8 | K34: Trevon Brazile F | L34: 13.1
B35: Amari Allen F | C35: 11.9 | E35: Jamarques Lawrence G | F35: 9.8 | H35: Melvin Council Jr. G | I35: 13.4 | K35: Billy Richmond III G | L35: 11.1
B36: Aiden Sherrell F | C36: 11 | E36: Sam Hoiberg G | F36: 9.7 | H36: Bryson Tiller F | I36: 8.3 | K36: Malique Ewin F | L36: 9.7
B37: Houston Mallette G | C37: 6.7 | E37: Berke Buyuktuncel F | F37: 6.6 | H37: Elmarko Jackson G | I37: 4.7 | K37: D.J. Wagner G | L37: 7.8
A39: 5 | B39: Texas Tech | E39: Vanderbilt | H39: St. John's | K39: Wisconsin
B40: Christian Anderson G** (Groin) | C40: 19.2 | E40: Tyler Tanner G | F40: 19.2 | H40: Zuby Ejiofor F | I40: 16 | K40: Nick Boyd G | L40: 20.1
B41: Donovan Atwell G | C41: 13.6 | E41: Duke Miles G | F41: 15.9 | H41: Bryce Hopkins F | I41: 13.3 | K41: John Blackwell G | L41: 18.3
B42: LeJuan Watts F** (Ankle) | C42: 11.5 | E42: Tyler Nickel F | F42: 13.7 | H42: Oziyah Sellers G | I42: 10.7 | K42: Nolan Winter F | L42: 13.3
B43: Jaylen Petty G | C43: 9.5 | E43: AK Okereke F | F43: 9.9 | H43: Ian Jackson G | I43: 9.8 | K43: Austin Rapp F | L43: 9.6
B44: Luke Bamgboye F | C44: 4.9 | E44: Devin McGlockton F | F44: 9.9 | H44: Joson Sanon G | I44: 8.3 | K44: Braeden Carrington G | L44: 8.6
B45: Josiah Moseley F | C45: 4.5 | E45: Jalen Washington C | F45: 9 | H45: Dillon Mitchell F | I45: 8.1 | K45: Andrew Rohde G | L45: 6
A47: 6 | B47: Tennessee | E47: North Carolina | H47: Louisville | K47: BYU
...
